Creating test database for alias 'default'...
........................................F..FF..E.F..EF.E.........................................................................................................................................
======================================================================
ERROR: test_risk_positions (succession.tests.SuccessionTest)
----------------------------------------------------------------------
Traceback (most recent call last):
  File "/home/fofloris/Documents/fo/web-framework/succession/tests.py", line 84, in test_risk_positions
    result = self.c.post('/succession/risk/positions', follow=True)
  File "/usr/lib/python3.3/site-packages/django/test/client.py", line 484, in post
    response = self._handle_redirects(response, **extra)
  File "/usr/lib/python3.3/site-packages/django/test/client.py", line 622, in _handle_redirects
    response = self.get(url.path, QueryDict(url.query), follow=False, **extra)
  File "/usr/lib/python3.3/site-packages/django/test/client.py", line 470, in get
    **extra)
  File "/usr/lib/python3.3/site-packages/django/test/client.py", line 286, in get
    return self.generic('GET', path, secure=secure, **r)
  File "/usr/lib/python3.3/site-packages/django/test/client.py", line 358, in generic
    return self.request(**r)
  File "/usr/lib/python3.3/site-packages/django/test/client.py", line 440, in request
    six.reraise(*exc_info)
  File "/usr/lib/python3.3/site-packages/django/utils/six.py", line 659, in reraise
    raise value
  File "/usr/lib/python3.3/site-packages/django/core/handlers/base.py", line 111, in get_response
    response = wrapped_callback(request, *callback_args, **callback_kwargs)
  File "/usr/lib/python3.3/site-packages/django/contrib/auth/decorators.py", line 21, in _wrapped_view
    return view_func(request, *args, **kwargs)
  File "/home/fofloris/Documents/fo/web-framework/succession/views.py", line 272, in risk_positions
    row.append(pos.job_set.get(status__active=True).employee.person.first_name + " " +
  File "/usr/lib/python3.3/site-packages/django/db/models/manager.py", line 92, in manager_method
    return getattr(self.get_queryset(), name)(*args, **kwargs)
  File "/usr/lib/python3.3/site-packages/django/db/models/query.py", line 357, in get
    self.model._meta.object_name)
database.models.DoesNotExist: Job matching query does not exist.

======================================================================
FAIL: test_headcount_overview (organisation.tests.OrganisationTest)
----------------------------------------------------------------------
Traceback (most recent call last):
  File "/home/fofloris/Documents/fo/web-framework/organisation/tests.py", line 69, in test_headcount_overview
    MultiPosition.objects.authorized(user).aggregate(Sum('headcount')).get('headcount__sum')
AssertionError: 390 != 393

======================================================================
FAIL: test_structure_layers_fte (organisation.tests.OrganisationTest)
----------------------------------------------------------------------
Traceback (most recent call last):
  File "/home/fofloris/Documents/fo/web-framework/organisation/tests.py", line 247, in test_structure_layers_fte
    self.assertTrue(all([x <= 100.0 for x in dt2.get_column_values(1)]))
AssertionError: False is not true

======================================================================
FAIL: test_structure_span_avg (organisation.tests.OrganisationTest)
----------------------------------------------------------------------
Traceback (most recent call last):
  File "/home/fofloris/Documents/fo/web-framework/organisation/tests.py", line 306, in test_structure_span_avg
    self.assertEqual(dt.get_value(0,0), sum([x.positionhierarchy.direct_span for x in phs])/len(phs))
AssertionError: 12.583333333333334 != 13.545454545454545

======================================================================
FAIL: test_overview_summary (succession.tests.SuccessionTest)
----------------------------------------------------------------------
Traceback (most recent call last):
  File "/home/fofloris/Documents/fo/web-framework/succession/tests.py", line 38, in test_overview_summary
    self.assertEqual(dt.get_value(0, i), n_pos)
AssertionError: 50.0 != 53

----------------------------------------------------------------------
Ran 193 tests in 586.105s

FAILED (failures=5, errors=3)
Destroying test database for alias 'default'...

